Traceback (most recent call last):
  File "/Users/zulfadzli/opt/anaconda3/lib/python3.9/site-packages/jupyter_cache/executors/utils.py", line 51, in single_nb_execution
    executenb(
  File "/Users/zulfadzli/opt/anaconda3/lib/python3.9/site-packages/nbclient/client.py", line 1204, in execute
    return NotebookClient(nb=nb, resources=resources, km=km, **kwargs).execute()
  File "/Users/zulfadzli/opt/anaconda3/lib/python3.9/site-packages/nbclient/util.py", line 84, in wrapped
    return just_run(coro(*args, **kwargs))
  File "/Users/zulfadzli/opt/anaconda3/lib/python3.9/site-packages/nbclient/util.py", line 62, in just_run
    return loop.run_until_complete(coro)
  File "/Users/zulfadzli/opt/anaconda3/lib/python3.9/asyncio/base_events.py", line 647, in run_until_complete
    return future.result()
  File "/Users/zulfadzli/opt/anaconda3/lib/python3.9/site-packages/nbclient/client.py", line 663, in async_execute
    await self.async_execute_cell(
  File "/Users/zulfadzli/opt/anaconda3/lib/python3.9/site-packages/nbclient/client.py", line 965, in async_execute_cell
    await self._check_raise_for_error(cell, cell_index, exec_reply)
  File "/Users/zulfadzli/opt/anaconda3/lib/python3.9/site-packages/nbclient/client.py", line 862, in _check_raise_for_error
    raise CellExecutionError.from_cell_and_msg(cell, exec_reply_content)
nbclient.exceptions.CellExecutionError: An error occurred while executing the following cell:
------------------
import folium
m = folium.Map(
    location=[45.372, -121.6972],
    zoom_start=12,
    tiles='Stamen Terrain'
)

folium.Marker(
    location=[45.3288, -121.6625],
    popup='Mt. Hood Meadows',
    icon=folium.Icon(icon='cloud')
).add_to(m)

folium.Marker(
    location=[45.3311, -121.7113],
    popup='Timberline Lodge',
    icon=folium.Icon(color='green')
).add_to(m)

folium.Marker(
    location=[45.3300, -121.6823],
    popup='Some Other Location',
    icon=folium.Icon(color='red', icon='info-sign')
).add_to(m)

m
------------------

[0;31m---------------------------------------------------------------------------[0m
[0;31mModuleNotFoundError[0m                       Traceback (most recent call last)
[0;32m/var/folders/mp/k8prchjx5yv8qpg7r0nnzfz80000gn/T/ipykernel_26121/2074828163.py[0m in [0;36m<module>[0;34m[0m
[0;32m----> 1[0;31m [0;32mimport[0m [0mfolium[0m[0;34m[0m[0;34m[0m[0m
[0m[1;32m      2[0m m = folium.Map(
[1;32m      3[0m     [0mlocation[0m[0;34m=[0m[0;34m[[0m[0;36m45.372[0m[0;34m,[0m [0;34m-[0m[0;36m121.6972[0m[0;34m][0m[0;34m,[0m[0;34m[0m[0;34m[0m[0m
[1;32m      4[0m     [0mzoom_start[0m[0;34m=[0m[0;36m12[0m[0;34m,[0m[0;34m[0m[0;34m[0m[0m
[1;32m      5[0m     [0mtiles[0m[0;34m=[0m[0;34m'Stamen Terrain'[0m[0;34m[0m[0;34m[0m[0m

[0;31mModuleNotFoundError[0m: No module named 'folium'
ModuleNotFoundError: No module named 'folium'

